Workbook

Sheet Risk Register
A1: Risk Register LumiPay v1.0 (14 Okt 2026): Analisis Risiko (langkah 3)
A2: Penilaian ini untuk kondisi saat ini (sebelum penanganan). Dampak diambil dari dimensi yang paling parah (MAX), lalu skor = kemungkinan x dampak.
A3: Legenda: sel biru berlatar kuning = nilai penilaian (boleh diubah, skala 1 sampai 5). Sel hitam = rumus, jangan diketik manual. Batas level dan penerimaan ada di sheet Kriteria.
A5: ID | B5: Aset | C5: Skenario risiko | D5: Pemilik risiko | E5: Kemungkinan (1-5) | F5: Dampak operasional layanan (1-5) | G5: Dampak finansial (1-5) | H5: Dampak reputasi (1-5) | I5: Dampak (maks) | J5: Skor | K5: Level | L5: Keputusan awal | M5: Alasan penilaian | N5: Kunci urutan prioritas (bantuan, jangan diubah)
A6: R-01 | B6: A-01 Database transaksi | C6: Data transaksi dicuri atau dimanipulasi lewat celah aplikasi | D6: Head of Engineering | E6: 3 | F6: 3 | G6: 4 | H6: 4 | I6: =MAX(F6:H6) -> 4 | J6: =E6*I6 -> 12 | K6: =IF(J6<=Kriteria!$B$3,"Rendah",IF(J6<=Kriteria!$B$4,"Sedang",IF(J6<=Kriteria!$B$5,"Tinggi","Kritis"))) -> Tinggi | L6: =IF(J6>Kriteria!$B$6,"Perlu ditangani",IF(J6>Kriteria!$B$3,"Dapat diterima, perlu persetujuan pemilik risiko","Diterima")) -> Perlu ditangani | M6: Validasi input lemah dan patch terlambat; dampak terbesar pada finansial dan reputasi. | N6: =J6+I6/100+E6/10000-ROW()/10000000 -> 12.040299
A7: R-02 | B7: A-02 Data KYC pengguna | C7: Data KTP dan swafoto pengguna bocor atau disalahgunakan | D7: Compliance Officer | E7: 3 | F7: 2 | G7: 3 | H7: 4 | I7: =MAX(F7:H7) -> 4 | J7: =E7*I7 -> 12 | K7: =IF(J7<=Kriteria!$B$3,"Rendah",IF(J7<=Kriteria!$B$4,"Sedang",IF(J7<=Kriteria!$B$5,"Tinggi","Kritis"))) -> Tinggi | L7: =IF(J7>Kriteria!$B$6,"Perlu ditangani",IF(J7>Kriteria!$B$3,"Dapat diterima, perlu persetujuan pemilik risiko","Diterima")) -> Perlu ditangani | M7: Hak akses luas dan belum ada MFA; kebocoran data pribadi memukul reputasi. | N7: =J7+I7/100+E7/10000-ROW()/10000000 -> 12.040299
A8: R-03 | B8: A-02 Data KYC pengguna | C8: File KYC terekspos ke internet | D8: Head of Infrastructure | E8: 2 | F8: 1 | G8: 3 | H8: 5 | I8: =MAX(F8:H8) -> 5 | J8: =E8*I8 -> 10 | K8: =IF(J8<=Kriteria!$B$3,"Rendah",IF(J8<=Kriteria!$B$4,"Sedang",IF(J8<=Kriteria!$B$5,"Tinggi","Kritis"))) -> Tinggi | L8: =IF(J8>Kriteria!$B$6,"Perlu ditangani",IF(J8>Kriteria!$B$3,"Dapat diterima, perlu persetujuan pemilik risiko","Diterima")) -> Perlu ditangani | M8: Salah konfigurasi jarang terjadi tetapi mungkin; jika terekspos, kepercayaan publik sangat terpukul. | N8: =J8+I8/100+E8/10000-ROW()/10000000 -> 10.050199
A9: R-04 | B9: A-03 Saldo dan ledger | C9: Saldo atau mutasi diubah tanpa terdeteksi | D9: Head of Finance Operations | E9: 2 | F9: 2 | G9: 5 | H9: 4 | I9: =MAX(F9:H9) -> 5 | J9: =E9*I9 -> 10 | K9: =IF(J9<=Kriteria!$B$3,"Rendah",IF(J9<=Kriteria!$B$4,"Sedang",IF(J9<=Kriteria!$B$5,"Tinggi","Kritis"))) -> Tinggi | L9: =IF(J9>Kriteria!$B$6,"Perlu ditangani",IF(J9>Kriteria!$B$3,"Dapat diterima, perlu persetujuan pemilik risiko","Diterima")) -> Perlu ditangani | M9: Tanpa pemisahan tugas dan rekonsiliasi manual; kejadian jarang, tetapi kerugian finansial besar. | N9: =J9+I9/100+E9/10000-ROW()/10000000 -> 10.050199
A10: R-05 | B10: A-04 Kunci enkripsi dan secret | C10: Kunci jatuh ke penyerang sehingga data terenkripsi bisa dibuka | D10: Head of Security | E10: 3 | F10: 3 | G10: 4 | H10: 4 | I10: =MAX(F10:H10) -> 4 | J10: =E10*I10 -> 12 | K10: =IF(J10<=Kriteria!$B$3,"Rendah",IF(J10<=Kriteria!$B$4,"Sedang",IF(J10<=Kriteria!$B$5,"Tinggi","Kritis"))) -> Tinggi | L10: =IF(J10>Kriteria!$B$6,"Perlu ditangani",IF(J10>Kriteria!$B$3,"Dapat diterima, perlu persetujuan pemilik risiko","Diterima")) -> Perlu ditangani | M10: Secret di kode atau chat membuat kebocoran cukup mungkin; efeknya berantai ke banyak sistem. | N10: =J10+I10/100+E10/10000-ROW()/10000000 -> 12.040299
A11: R-06 | B11: A-05 Kode sumber dan pipeline CI/CD | C11: Kode sumber bocor sehingga celah aplikasi dan logika bisnis terlihat pihak yang tidak berwenang | D11: Head of Engineering | E11: 3 | F11: 2 | G11: 2 | H11: 3 | I11: =MAX(F11:H11) -> 3 | J11: =E11*I11 -> 9 | K11: =IF(J11<=Kriteria!$B$3,"Rendah",IF(J11<=Kriteria!$B$4,"Sedang",IF(J11<=Kriteria!$B$5,"Tinggi","Kritis"))) -> Sedang | L11: =IF(J11>Kriteria!$B$6,"Perlu ditangani",IF(J11>Kriteria!$B$3,"Dapat diterima, perlu persetujuan pemilik risiko","Diterima")) -> Dapat diterima, perlu persetujuan pemilik risiko | M11: Akun mantan karyawan masih aktif dan tanpa MFA, repositori bisa dipublikasikan tanpa kontrol; kebocoran kode membuka celah aplikasi dan kekayaan intelektual. Secret di dalam kode dicakup R-05, perubahan kode tanpa izin dicakup R-07. | N11: =J11+I11/100+E11/10000-ROW()/10000000 -> 9.0302989
A12: R-07 | B12: A-05 Kode sumber dan pipeline CI/CD | C12: Kode atau pipeline diubah tanpa izin sehingga kode berbahaya masuk ke produksi dan dana atau data pengguna disalahgunakan | D12: Head of Engineering | E12: 3 | F12: 4 | G12: 5 | H12: 5 | I12: =MAX(F12:H12) -> 5 | J12: =E12*I12 -> 15 | K12: =IF(J12<=Kriteria!$B$3,"Rendah",IF(J12<=Kriteria!$B$4,"Sedang",IF(J12<=Kriteria!$B$5,"Tinggi","Kritis"))) -> Tinggi | L12: =IF(J12>Kriteria!$B$6,"Perlu ditangani",IF(J12>Kriteria!$B$3,"Dapat diterima, perlu persetujuan pemilik risiko","Diterima")) -> Perlu ditangani | M12: Kerentanan akses sama dengan R-06 (tanpa MFA, akun mantan karyawan aktif), ditambah belum ada branch protection dan review wajib. Kode berbahaya di aplikasi pembayaran bisa mengalihkan dana dan memengaruhi semua pengguna, jadi dampak dinilai paling parah. Beda dengan R-06: ini soal integritas, bukan kerahasiaan. | N12: =J12+I12/100+E12/10000-ROW()/10000000 -> 15.050299
A13: R-08 | B13: A-06 Dokumen kebijakan dan kontrak | C13: Kebijakan usang atau berubah tanpa persetujuan, kewajiban hukum terlewat | D13: Compliance Officer | E13: 3 | F13: 1 | G13: 2 | H13: 2 | I13: =MAX(F13:H13) -> 2 | J13: =E13*I13 -> 6 | K13: =IF(J13<=Kriteria!$B$3,"Rendah",IF(J13<=Kriteria!$B$4,"Sedang",IF(J13<=Kriteria!$B$5,"Tinggi","Kritis"))) -> Sedang | L13: =IF(J13>Kriteria!$B$6,"Perlu ditangani",IF(J13>Kriteria!$B$3,"Dapat diterima, perlu persetujuan pemilik risiko","Diterima")) -> Dapat diterima, perlu persetujuan pemilik risiko | M13: Tanpa kontrol versi; dampak operasional kecil, tetapi bisa memicu temuan kepatuhan. | N13: =J13+I13/100+E13/10000-ROW()/10000000 -> 6.0202987
A14: R-09 | B14: A-07 Aplikasi mobile | C14: Aplikasi palsu mencuri kredensial pengguna | D14: Product Owner | E14: 3 | F14: 1 | G14: 3 | H14: 3 | I14: =MAX(F14:H14) -> 3 | J14: =E14*I14 -> 9 | K14: =IF(J14<=Kriteria!$B$3,"Rendah",IF(J14<=Kriteria!$B$4,"Sedang",IF(J14<=Kriteria!$B$5,"Tinggi","Kritis"))) -> Sedang | L14: =IF(J14>Kriteria!$B$6,"Perlu ditangani",IF(J14>Kriteria!$B$3,"Dapat diterima, perlu persetujuan pemilik risiko","Diterima")) -> Dapat diterima, perlu persetujuan pemilik risiko | M14: Aplikasi tiruan cukup umum di sektor dompet digital; tidak ada proteksi integritas aplikasi. | N14: =J14+I14/100+E14/10000-ROW()/10000000 -> 9.0302986
A15: R-10 | B15: A-08 API payment gateway | C15: API tidak tersedia, transaksi merchant gagal | D15: Head of Engineering | E15: 4 | F15: 4 | G15: 3 | H15: 3 | I15: =MAX(F15:H15) -> 4 | J15: =E15*I15 -> 16 | K15: =IF(J15<=Kriteria!$B$3,"Rendah",IF(J15<=Kriteria!$B$4,"Sedang",IF(J15<=Kriteria!$B$5,"Tinggi","Kritis"))) -> Tinggi | L15: =IF(J15>Kriteria!$B$6,"Perlu ditangani",IF(J15>Kriteria!$B$3,"Dapat diterima, perlu persetujuan pemilik risiko","Diterima")) -> Perlu ditangani | M15: Tanpa rate limiting dan proteksi DDoS yang memadai; serangan ke API pembayaran sering terjadi. | N15: =J15+I15/100+E15/10000-ROW()/10000000 -> 16.040398
A16: R-11 | B16: A-08 API payment gateway | C16: Penyerang mengakses transaksi merchant lain | D16: Head of Engineering | E16: 3 | F16: 2 | G16: 4 | H16: 4 | I16: =MAX(F16:H16) -> 4 | J16: =E16*I16 -> 12 | K16: =IF(J16<=Kriteria!$B$3,"Rendah",IF(J16<=Kriteria!$B$4,"Sedang",IF(J16<=Kriteria!$B$5,"Tinggi","Kritis"))) -> Tinggi | L16: =IF(J16>Kriteria!$B$6,"Perlu ditangani",IF(J16>Kriteria!$B$3,"Dapat diterima, perlu persetujuan pemilik risiko","Diterima")) -> Perlu ditangani | M16: Otorisasi per objek lemah; celah semacam ini umum di API. | N16: =J16+I16/100+E16/10000-ROW()/10000000 -> 12.040298
A17: R-12 | B17: A-09 Dasbor merchant | C17: Akun merchant diambil alih dan dana dialihkan | D17: Product Owner | E17: 4 | F17: 2 | G17: 3 | H17: 3 | I17: =MAX(F17:H17) -> 3 | J17: =E17*I17 -> 12 | K17: =IF(J17<=Kriteria!$B$3,"Rendah",IF(J17<=Kriteria!$B$4,"Sedang",IF(J17<=Kriteria!$B$5,"Tinggi","Kritis"))) -> Tinggi | L17: =IF(J17>Kriteria!$B$6,"Perlu ditangani",IF(J17>Kriteria!$B$3,"Dapat diterima, perlu persetujuan pemilik risiko","Diterima")) -> Perlu ditangani | M17: Credential stuffing sangat umum; MFA masih opsional. | N17: =J17+I17/100+E17/10000-ROW()/10000000 -> 12.030398
... A27: R-22 | B27: A-17 Personel kunci | C27: Pengetahuan kritis hilang dan akses mantan karyawan masih aktif | D27: Head of HR | E27: 3 | F27: 3 | G27: 2 | H27: 2 | I27: =MAX(F27:H27) -> 3 | J27: =E27*I27 -> 9 | K27: =IF(J27<=Kriteria!$B$3,"Rendah",IF(J27<=Kriteria!$B$4,"Sedang",IF(J27<=Kriteria!$B$5,"Tinggi","Kritis"))) -> Sedang | L27: =IF(J27>Kriteria!$B$6,"Perlu ditangani",IF(J27>Kriteria!$B$3,"Dapat diterima, perlu persetujuan pemilik risiko","Diterima")) -> Dapat diterima, perlu persetujuan pemilik risiko | M27: Ketergantungan pada satu orang dan offboarding tidak teratur; perputaran karyawan wajar terjadi. | N27: =J27+I27/100+E27/10000-ROW()/10000000 -> 9.0302973

Sheet Evaluasi
A1: Evaluasi Risiko LumiPay (langkah 4)
A2: Skor tiap risiko dibandingkan dengan batas penerimaan (sheet Kriteria), lalu diurutkan dari yang paling mendesak.
A3: Aturan urutan: skor tertinggi dulu; jika sama, dampak tertinggi dulu; jika masih sama, kemungkinan tertinggi dulu; terakhir urutan ID.
A4: Legenda: sel biru berlatar kuning = parameter tenggat (boleh diubah). Kolom lain berisi rumus yang membaca Risk Register.
A6: Tenggat penanganan level Tinggi (hari) | D6: 90
A7: Tenggat penanganan level Kritis (hari) | D7: 30
A9: Prioritas | B9: ID | C9: Skenario risiko | D9: Pemilik risiko | E9: Skor | F9: Level | G9: Keputusan evaluasi | H9: Tenggat penanganan | I9: Pihak yang menyetujui
A10: 1 | B10: =INDEX('Risk Register'!$A$6:$A$27,MATCH(LARGE('Risk Register'!$N$6:$N$27,$A10),'Risk Register'!$N$6:$N$27,0)) -> R-10 | C10: =INDEX('Risk Register'!$C$6:$C$27,MATCH(LARGE('Risk Register'!$N$6:$N$27,$A10),'Risk Register'!$N$6:$N$27,0)) -> API tidak tersedia, transaksi merchant gagal | D10: =INDEX('Risk Register'!$D$6:$D$27,MATCH(LARGE('Risk Register'!$N$6:$N$27,$A10),'Risk Register'!$N$6:$N$27,0)) -> Head of Engineering | E10: =INDEX('Risk Register'!$J$6:$J$27,MATCH(LARGE('Risk Register'!$N$6:$N$27,$A10),'Risk Register'!$N$6:$N$27,0)) -> 16 | F10: =INDEX('Risk Register'!$K$6:$K$27,MATCH(LARGE('Risk Register'!$N$6:$N$27,$A10),'Risk Register'!$N$6:$N$27,0)) -> Tinggi | G10: =INDEX('Risk Register'!$L$6:$L$27,MATCH(LARGE('Risk Register'!$N$6:$N$27,$A10),'Risk Register'!$N$6:$N$27,0)) -> Perlu ditangani | H10: =IF(F10="Kritis","Dalam "&$D$7&" hari",IF(F10="Tinggi","Dalam "&$D$6&" hari",IF(F10="Sedang","Tinjau tiap 6 bulan","Pantau saat tinjauan berkala"))) -> Dalam 90 hari | I10: =IF(F10="Kritis","Direksi",IF(F10="Tinggi","Manajemen (risiko sisa)",IF(F10="Sedang","Pemilik risiko","Tidak perlu"))) -> Manajemen (risiko sisa)
A11: 2 | B11: =INDEX('Risk Register'!$A$6:$A$27,MATCH(LARGE('Risk Register'!$N$6:$N$27,$A11),'Risk Register'!$N$6:$N$27,0)) -> R-18 | C11: =INDEX('Risk Register'!$C$6:$C$27,MATCH(LARGE('Risk Register'!$N$6:$N$27,$A11),'Risk Register'!$N$6:$N$27,0)) -> Karyawan menyerahkan kredensial dan penyerang masuk ke sistem | D11: =INDEX('Risk Register'!$D$6:$D$27,MATCH(LARGE('Risk Register'!$N$6:$N$27,$A11),'Risk Register'!$N$6:$N$27,0)) -> Head of IT Support | E11: =INDEX('Risk Register'!$J$6:$J$27,MATCH(LARGE('Risk Register'!$N$6:$N$27,$A11),'Risk Register'!$N$6:$N$27,0)) -> 16 | F11: =INDEX('Risk Register'!$K$6:$K$27,MATCH(LARGE('Risk Register'!$N$6:$N$27,$A11),'Risk Register'!$N$6:$N$27,0)) -> Tinggi | G11: =INDEX('Risk Register'!$L$6:$L$27,MATCH(LARGE('Risk Register'!$N$6:$N$27,$A11),'Risk Register'!$N$6:$N$27,0)) -> Perlu ditangani | H11: =IF(F11="Kritis","Dalam "&$D$7&" hari",IF(F11="Tinggi","Dalam "&$D$6&" hari",IF(F11="Sedang","Tinjau tiap 6 bulan","Pantau saat tinjauan berkala"))) -> Dalam 90 hari | I11: =IF(F11="Kritis","Direksi",IF(F11="Tinggi","Manajemen (risiko sisa)",IF(F11="Sedang","Pemilik risiko","Tidak perlu"))) -> Manajemen (risiko sisa)
A12: 3 | B12: =INDEX('Risk Register'!$A$6:$A$27,MATCH(LARGE('Risk Register'!$N$6:$N$27,$A12),'Risk Register'!$N$6:$N$27,0)) -> R-07 | C12: =INDEX('Risk Register'!$C$6:$C$27,MATCH(LARGE('Risk Register'!$N$6:$N$27,$A12),'Risk Register'!$N$6:$N$27,0)) -> Kode atau pipeline diubah tanpa izin sehingga kode berbahaya masuk ke produksi dan dana atau data pengguna disalahgunakan | D12: =INDEX('Risk Register'!$D$6:$D$27,MATCH(LARGE('Risk Register'!$N$6:$N$27,$A12),'Risk Register'!$N$6:$N$27,0)) -> Head of Engineering | E12: =INDEX('Risk Register'!$J$6:$J$27,MATCH(LARGE('Risk Register'!$N$6:$N$27,$A12),'Risk Register'!$N$6:$N$27,0)) -> 15 | F12: =INDEX('Risk Register'!$K$6:$K$27,MATCH(LARGE('Risk Register'!$N$6:$N$27,$A12),'Risk Register'!$N$6:$N$27,0)) -> Tinggi | G12: =INDEX('Risk Register'!$L$6:$L$27,MATCH(LARGE('Risk Register'!$N$6:$N$27,$A12),'Risk Register'!$N$6:$N$27,0)) -> Perlu ditangani | H12: =IF(F12="Kritis","Dalam "&$D$7&" hari",IF(F12="Tinggi","Dalam "&$D$6&" hari",IF(F12="Sedang","Tinjau tiap 6 bulan","Pantau saat tinjauan berkala"))) -> Dalam 90 hari | I12: =IF(F12="Kritis","Direksi",IF(F12="Tinggi","Manajemen (risiko sisa)",IF(F12="Sedang","Pemilik risiko","Tidak perlu"))) -> Manajemen (risiko sisa)
A13: 4 | B13: =INDEX('Risk Register'!$A$6:$A$27,MATCH(LARGE('Risk Register'!$N$6:$N$27,$A13),'Risk Register'!$N$6:$N$27,0)) -> R-01 | C13: =INDEX('Risk Register'!$C$6:$C$27,MATCH(LARGE('Risk Register'!$N$6:$N$27,$A13),'Risk Register'!$N$6:$N$27,0)) -> Data transaksi dicuri atau dimanipulasi lewat celah aplikasi | D13: =INDEX('Risk Register'!$D$6:$D$27,MATCH(LARGE('Risk Register'!$N$6:$N$27,$A13),'Risk Register'!$N$6:$N$27,0)) -> Head of Engineering | E13: =INDEX('Risk Register'!$J$6:$J$27,MATCH(LARGE('Risk Register'!$N$6:$N$27,$A13),'Risk Register'!$N$6:$N$27,0)) -> 12 | F13: =INDEX('Risk Register'!$K$6:$K$27,MATCH(LARGE('Risk Register'!$N$6:$N$27,$A13),'Risk Register'!$N$6:$N$27,0)) -> Tinggi | G13: =INDEX('Risk Register'!$L$6:$L$27,MATCH(LARGE('Risk Register'!$N$6:$N$27,$A13),'Risk Register'!$N$6:$N$27,0)) -> Perlu ditangani | H13: =IF(F13="Kritis","Dalam "&$D$7&" hari",IF(F13="Tinggi","Dalam "&$D$6&" hari",IF(F13="Sedang","Tinjau tiap 6 bulan","Pantau saat tinjauan berkala"))) -> Dalam 90 hari | I13: =IF(F13="Kritis","Direksi",IF(F13="Tinggi","Manajemen (risiko sisa)",IF(F13="Sedang","Pemilik risiko","Tidak perlu"))) -> Manajemen (risiko sisa)
A14: 5 | B14: =INDEX('Risk Register'!$A$6:$A$27,MATCH(LARGE('Risk Register'!$N$6:$N$27,$A14),'Risk Register'!$N$6:$N$27,0)) -> R-02 | C14: =INDEX('Risk Register'!$C$6:$C$27,MATCH(LARGE('Risk Register'!$N$6:$N$27,$A14),'Risk Register'!$N$6:$N$27,0)) -> Data KTP dan swafoto pengguna bocor atau disalahgunakan | D14: =INDEX('Risk Register'!$D$6:$D$27,MATCH(LARGE('Risk Register'!$N$6:$N$27,$A14),'Risk Register'!$N$6:$N$27,0)) -> Compliance Officer | E14: =INDEX('Risk Register'!$J$6:$J$27,MATCH(LARGE('Risk Register'!$N$6:$N$27,$A14),'Risk Register'!$N$6:$N$27,0)) -> 12 | F14: =INDEX('Risk Register'!$K$6:$K$27,MATCH(LARGE('Risk Register'!$N$6:$N$27,$A14),'Risk Register'!$N$6:$N$27,0)) -> Tinggi | G14: =INDEX('Risk Register'!$L$6:$L$27,MATCH(LARGE('Risk Register'!$N$6:$N$27,$A14),'Risk Register'!$N$6:$N$27,0)) -> Perlu ditangani | H14: =IF(F14="Kritis","Dalam "&$D$7&" hari",IF(F14="Tinggi","Dalam "&$D$6&" hari",IF(F14="Sedang","Tinjau tiap 6 bulan","Pantau saat tinjauan berkala"))) -> Dalam 90 hari | I14: =IF(F14="Kritis","Direksi",IF(F14="Tinggi","Manajemen (risiko sisa)",IF(F14="Sedang","Pemilik risiko","Tidak perlu"))) -> Manajemen (risiko sisa)
A15: 6 | B15: =INDEX('Risk Register'!$A$6:$A$27,MATCH(LARGE('Risk Register'!$N$6:$N$27,$A15),'Risk Register'!$N$6:$N$27,0)) -> R-05 | C15: =INDEX('Risk Register'!$C$6:$C$27,MATCH(LARGE('Risk Register'!$N$6:$N$27,$A15),'Risk Register'!$N$6:$N$27,0)) -> Kunci jatuh ke penyerang sehingga data terenkripsi bisa dibuka | D15: =INDEX('Risk Register'!$D$6:$D$27,MATCH(LARGE('Risk Register'!$N$6:$N$27,$A15),'Risk Register'!$N$6:$N$27,0)) -> Head of Security | E15: =INDEX('Risk Register'!$J$6:$J$27,MATCH(LARGE('Risk Register'!$N$6:$N$27,$A15),'Risk Register'!$N$6:$N$27,0)) -> 12 | F15: =INDEX('Risk Register'!$K$6:$K$27,MATCH(LARGE('Risk Register'!$N$6:$N$27,$A15),'Risk Register'!$N$6:$N$27,0)) -> Tinggi | G15: =INDEX('Risk Register'!$L$6:$L$27,MATCH(LARGE('Risk Register'!$N$6:$N$27,$A15),'Risk Register'!$N$6:$N$27,0)) -> Perlu ditangani | H15: =IF(F15="Kritis","Dalam "&$D$7&" hari",IF(F15="Tinggi","Dalam "&$D$6&" hari",IF(F15="Sedang","Tinjau tiap 6 bulan","Pantau saat tinjauan berkala"))) -> Dalam 90 hari | I15: =IF(F15="Kritis","Direksi",IF(F15="Tinggi","Manajemen (risiko sisa)",IF(F15="Sedang","Pemilik risiko","Tidak perlu"))) -> Manajemen (risiko sisa)
A16: 7 | B16: =INDEX('Risk Register'!$A$6:$A$27,MATCH(LARGE('Risk Register'!$N$6:$N$27,$A16),'Risk Register'!$N$6:$N$27,0)) -> R-11 | C16: =INDEX('Risk Register'!$C$6:$C$27,MATCH(LARGE('Risk Register'!$N$6:$N$27,$A16),'Risk Register'!$N$6:$N$27,0)) -> Penyerang mengakses transaksi merchant lain | D16: =INDEX('Risk Register'!$D$6:$D$27,MATCH(LARGE('Risk Register'!$N$6:$N$27,$A16),'Risk Register'!$N$6:$N$27,0)) -> Head of Engineering | E16: =INDEX('Risk Register'!$J$6:$J$27,MATCH(LARGE('Risk Register'!$N$6:$N$27,$A16),'Risk Register'!$N$6:$N$27,0)) -> 12 | F16: =INDEX('Risk Register'!$K$6:$K$27,MATCH(LARGE('Risk Register'!$N$6:$N$27,$A16),'Risk Register'!$N$6:$N$27,0)) -> Tinggi | G16: =INDEX('Risk Register'!$L$6:$L$27,MATCH(LARGE('Risk Register'!$N$6:$N$27,$A16),'Risk Register'!$N$6:$N$27,0)) -> Perlu ditangani | H16: =IF(F16="Kritis","Dalam "&$D$7&" hari",IF(F16="Tinggi","Dalam "&$D$6&" hari",IF(F16="Sedang","Tinjau tiap 6 bulan","Pantau saat tinjauan berkala"))) -> Dalam 90 hari | I16: =IF(F16="Kritis","Direksi",IF(F16="Tinggi","Manajemen (risiko sisa)",IF(F16="Sedang","Pemilik risiko","Tidak perlu"))) -> Manajemen (risiko sisa)
A17: 8 | B17: =INDEX('Risk Register'!$A$6:$A$27,MATCH(LARGE('Risk Register'!$N$6:$N$27,$A17),'Risk Register'!$N$6:$N$27,0)) -> R-12 | C17: =INDEX('Risk Register'!$C$6:$C$27,MATCH(LARGE('Risk Register'!$N$6:$N$27,$A17),'Risk Register'!$N$6:$N$27,0)) -> Akun merchant diambil alih dan dana dialihkan | D17: =INDEX('Risk Register'!$D$6:$D$27,MATCH(LARGE('Risk Register'!$N$6:$N$27,$A17),'Risk Register'!$N$6:$N$27,0)) -> Product Owner | E17: =INDEX('Risk Register'!$J$6:$J$27,MATCH(LARGE('Risk Register'!$N$6:$N$27,$A17),'Risk Register'!$N$6:$N$27,0)) -> 12 | F17: =INDEX('Risk Register'!$K$6:$K$27,MATCH(LARGE('Risk Register'!$N$6:$N$27,$A17),'Risk Register'!$N$6:$N$27,0)) -> Tinggi | G17: =INDEX('Risk Register'!$L$6:$L$27,MATCH(LARGE('Risk Register'!$N$6:$N$27,$A17),'Risk Register'!$N$6:$N$27,0)) -> Perlu ditangani | H17: =IF(F17="Kritis","Dalam "&$D$7&" hari",IF(F17="Tinggi","Dalam "&$D$6&" hari",IF(F17="Sedang","Tinjau tiap 6 bulan","Pantau saat tinjauan berkala"))) -> Dalam 90 hari | I17: =IF(F17="Kritis","Direksi",IF(F17="Tinggi","Manajemen (risiko sisa)",IF(F17="Sedang","Pemilik risiko","Tidak perlu"))) -> Manajemen (risiko sisa)
A18: 9 | B18: =INDEX('Risk Register'!$A$6:$A$27,MATCH(LARGE('Risk Register'!$N$6:$N$27,$A18),'Risk Register'!$N$6:$N$27,0)) -> R-03 | C18: =INDEX('Risk Register'!$C$6:$C$27,MATCH(LARGE('Risk Register'!$N$6:$N$27,$A18),'Risk Register'!$N$6:$N$27,0)) -> File KYC terekspos ke internet | D18: =INDEX('Risk Register'!$D$6:$D$27,MATCH(LARGE('Risk Register'!$N$6:$N$27,$A18),'Risk Register'!$N$6:$N$27,0)) -> Head of Infrastructure | E18: =INDEX('Risk Register'!$J$6:$J$27,MATCH(LARGE('Risk Register'!$N$6:$N$27,$A18),'Risk Register'!$N$6:$N$27,0)) -> 10 | F18: =INDEX('Risk Register'!$K$6:$K$27,MATCH(LARGE('Risk Register'!$N$6:$N$27,$A18),'Risk Register'!$N$6:$N$27,0)) -> Tinggi | G18: =INDEX('Risk Register'!$L$6:$L$27,MATCH(LARGE('Risk Register'!$N$6:$N$27,$A18),'Risk Register'!$N$6:$N$27,0)) -> Perlu ditangani | H18: =IF(F18="Kritis","Dalam "&$D$7&" hari",IF(F18="Tinggi","Dalam "&$D$6&" hari",IF(F18="Sedang","Tinjau tiap 6 bulan","Pantau saat tinjauan berkala"))) -> Dalam 90 hari | I18: =IF(F18="Kritis","Direksi",IF(F18="Tinggi","Manajemen (risiko sisa)",IF(F18="Sedang","Pemilik risiko","Tidak perlu"))) -> Manajemen (risiko sisa)
A19: 10 | B19: =INDEX('Risk Register'!$A$6:$A$27,MATCH(LARGE('Risk Register'!$N$6:$N$27,$A19),'Risk Register'!$N$6:$N$27,0)) -> R-04 | C19: =INDEX('Risk Register'!$C$6:$C$27,MATCH(LARGE('Risk Register'!$N$6:$N$27,$A19),'Risk Register'!$N$6:$N$27,0)) -> Saldo atau mutasi diubah tanpa terdeteksi | D19: =INDEX('Risk Register'!$D$6:$D$27,MATCH(LARGE('Risk Register'!$N$6:$N$27,$A19),'Risk Register'!$N$6:$N$27,0)) -> Head of Finance Operations | E19: =INDEX('Risk Register'!$J$6:$J$27,MATCH(LARGE('Risk Register'!$N$6:$N$27,$A19),'Risk Register'!$N$6:$N$27,0)) -> 10 | F19: =INDEX('Risk Register'!$K$6:$K$27,MATCH(LARGE('Risk Register'!$N$6:$N$27,$A19),'Risk Register'!$N$6:$N$27,0)) -> Tinggi | G19: =INDEX('Risk Register'!$L$6:$L$27,MATCH(LARGE('Risk Register'!$N$6:$N$27,$A19),'Risk Register'!$N$6:$N$27,0)) -> Perlu ditangani | H19: =IF(F19="Kritis","Dalam "&$D$7&" hari",IF(F19="Tinggi","Dalam "&$D$6&" hari",IF(F19="Sedang","Tinjau tiap 6 bulan","Pantau saat tinjauan berkala"))) -> Dalam 90 hari | I19: =IF(F19="Kritis","Direksi",IF(F19="Tinggi","Manajemen (risiko sisa)",IF(F19="Sedang","Pemilik risiko","Tidak perlu"))) -> Manajemen (risiko sisa)
A20: 11 | B20: =INDEX('Risk Register'!$A$6:$A$27,MATCH(LARGE('Risk Register'!$N$6:$N$27,$A20),'Risk Register'!$N$6:$N$27,0)) -> R-15 | C20: =INDEX('Risk Register'!$C$6:$C$27,MATCH(LARGE('Risk Register'!$N$6:$N$27,$A20),'Risk Register'!$N$6:$N$27,0)) -> Data produksi terenkripsi dan backup ikut rusak | D20: =INDEX('Risk Register'!$D$6:$D$27,MATCH(LARGE('Risk Register'!$N$6:$N$27,$A20),'Risk Register'!$N$6:$N$27,0)) -> Head of Infrastructure | E20: =INDEX('Risk Register'!$J$6:$J$27,MATCH(LARGE('Risk Register'!$N$6:$N$27,$A20),'Risk Register'!$N$6:$N$27,0)) -> 10 | F20: =INDEX('Risk Register'!$K$6:$K$27,MATCH(LARGE('Risk Register'!$N$6:$N$27,$A20),'Risk Register'!$N$6:$N$27,0)) -> Tinggi | G20: =INDEX('Risk Register'!$L$6:$L$27,MATCH(LARGE('Risk Register'!$N$6:$N$27,$A20),'Risk Register'!$N$6:$N$27,0)) -> Perlu ditangani | H20: =IF(F20="Kritis","Dalam "&$D$7&" hari",IF(F20="Tinggi","Dalam "&$D$6&" hari",IF(F20="Sedang","Tinjau tiap 6 bulan","Pantau saat tinjauan berkala"))) -> Dalam 90 hari | I20: =IF(F20="Kritis","Direksi",IF(F20="Tinggi","Manajemen (risiko sisa)",IF(F20="Sedang","Pemilik risiko","Tidak perlu"))) -> Manajemen (risiko sisa)
A21: 12 | B21: =INDEX('Risk Register'!$A$6:$A$27,MATCH(LARGE('Risk Register'!$N$6:$N$27,$A21),'Risk Register'!$N$6:$N$27,0)) -> R-20 | C21: =INDEX('Risk Register'!$C$6:$C$27,MATCH(LARGE('Risk Register'!$N$6:$N$27,$A21),'Risk Register'!$N$6:$N$27,0)) -> Data KYC pengguna bocor dari penyedia | D21: =INDEX('Risk Register'!$D$6:$D$27,MATCH(LARGE('Risk Register'!$N$6:$N$27,$A21),'Risk Register'!$N$6:$N$27,0)) -> Compliance Officer | E21: =INDEX('Risk Register'!$J$6:$J$27,MATCH(LARGE('Risk Register'!$N$6:$N$27,$A21),'Risk Register'!$N$6:$N$27,0)) -> 10 | F21: =INDEX('Risk Register'!$K$6:$K$27,MATCH(LARGE('Risk Register'!$N$6:$N$27,$A21),'Risk Register'!$N$6:$N$27,0)) -> Tinggi | G21: =INDEX('Risk Register'!$L$6:$L$27,MATCH(LARGE('Risk Register'!$N$6:$N$27,$A21),'Risk Register'!$N$6:$N$27,0)) -> Perlu ditangani | H21: =IF(F21="Kritis","Dalam "&$D$7&" hari",IF(F21="Tinggi","Dalam "&$D$6&" hari",IF(F21="Sedang","Tinjau tiap 6 bulan","Pantau saat tinjauan berkala"))) -> Dalam 90 hari | I21: =IF(F21="Kritis","Direksi",IF(F21="Tinggi","Manajemen (risiko sisa)",IF(F21="Sedang","Pemilik risiko","Tidak perlu"))) -> Manajemen (risiko sisa)
... A31: 22 | B31: =INDEX('Risk Register'!$A$6:$A$27,MATCH(LARGE('Risk Register'!$N$6:$N$27,$A31),'Risk Register'!$N$6:$N$27,0)) -> R-08 | C31: =INDEX('Risk Register'!$C$6:$C$27,MATCH(LARGE('Risk Register'!$N$6:$N$27,$A31),'Risk Register'!$N$6:$N$27,0)) -> Kebijakan usang atau berubah tanpa persetujuan, kewajiban hukum terlewat | D31: =INDEX('Risk Register'!$D$6:$D$27,MATCH(LARGE('Risk Register'!$N$6:$N$27,$A31),'Risk Register'!$N$6:$N$27,0)) -> Compliance Officer | E31: =INDEX('Risk Register'!$J$6:$J$27,MATCH(LARGE('Risk Register'!$N$6:$N$27,$A31),'Risk Register'!$N$6:$N$27,0)) -> 6 | F31: =INDEX('Risk Register'!$K$6:$K$27,MATCH(LARGE('Risk Register'!$N$6:$N$27,$A31),'Risk Register'!$N$6:$N$27,0)) -> Sedang | G31: =INDEX('Risk Register'!$L$6:$L$27,MATCH(LARGE('Risk Register'!$N$6:$N$27,$A31),'Risk Register'!$N$6:$N$27,0)) -> Dapat diterima, perlu persetujuan pemilik risiko | H31: =IF(F31="Kritis","Dalam "&$D$7&" hari",IF(F31="Tinggi","Dalam "&$D$6&" hari",IF(F31="Sedang","Tinjau tiap 6 bulan","Pantau saat tinjauan berkala"))) -> Tinjau tiap 6 bulan | I31: =IF(F31="Kritis","Direksi",IF(F31="Tinggi","Manajemen (risiko sisa)",IF(F31="Sedang","Pemilik risiko","Tidak perlu"))) -> Pemilik risiko
A33: Catatan: batas penerimaan ada di sheet Kriteria (skor 9). Tenggat 90 dan 30 hari adalah parameter rekaan untuk LumiPay.

Sheet Penanganan
A1: Rencana Penanganan Risiko LumiPay v1.0 (14 Okt 2026) (langkah 5)
A2: Untuk tiap risiko dipilih opsi penanganan (mitigasi, terima, hindari, atau transfer), kontrol Annex A 2022, dan diperkirakan risiko sisa setelah kontrol diterapkan.
A3: Risiko dengan akar masalah sama ditangani bersama dalam satu kelompok (lihat sheet Kelompok). Kontrol di sini menjadi bahan untuk SoA (langkah 6).
A4: Legenda: sel biru berlatar kuning = nilai yang diisi (tanggal, nilai kemungkinan dan dampak risiko sisa). Kolom lain berisi rumus atau teks usulan.
A6: Tanggal penetapan rencana | D6: 46307
A9: ID | B9: Kelompok | C9: Skenario risiko | D9: Skor awal | E9: Level awal | F9: Prioritas evaluasi | G9: Opsi penanganan | H9: Kontrol Annex A (2022) | I9: Tindakan penanganan | J9: Alasan pemilihan opsi | K9: Penanggung jawab | L9: Target selesai atau tinjau | M9: Kemungkinan sisa (1-5) | N9: Dampak sisa (1-5) | O9: Skor sisa | P9: Level sisa | Q9: Status risiko sisa | R9: Penyetuju risiko sisa
A10: R-01 | B10: G3 | C10: =INDEX('Risk Register'!$C$6:$C$27,MATCH($A10,'Risk Register'!$A$6:$A$27,0)) -> Data transaksi dicuri atau dimanipulasi lewat celah aplikasi | D10: =INDEX('Risk Register'!$J$6:$J$27,MATCH($A10,'Risk Register'!$A$6:$A$27,0)) -> 12 | E10: =INDEX('Risk Register'!$K$6:$K$27,MATCH($A10,'Risk Register'!$A$6:$A$27,0)) -> Tinggi | F10: =MATCH($A10,Evaluasi!$B$10:$B$31,0) -> 4 | G10: Mitigasi | H10: 8.26, 8.28, 8.29, 8.8 | I10: Validasi input dan query berparameter pada semua akses database; code review dan pengujian keamanan (SAST dan pentest) sebelum rilis; patch kerentanan kritis maksimal 14 hari. | J10: Skor 12 di atas batas; kontrol pencegahan di tingkat kode paling efektif menurunkan kemungkinan. | K10: =INDEX('Risk Register'!$D$6:$D$27,MATCH($A10,'Risk Register'!$A$6:$A$27,0)) -> Head of Engineering | L10: =IF(G10="Terima",EDATE($D$6,6),$D$6+Evaluasi!$D$6) -> 46397 | M10: 2 | N10: 4 | O10: =M10*N10 -> 8 | P10: =IF(O10<=Kriteria!$B$3,"Rendah",IF(O10<=Kriteria!$B$4,"Sedang",IF(O10<=Kriteria!$B$5,"Tinggi","Kritis"))) -> Sedang | Q10: =IF(O10>Kriteria!$B$6,"Perlu penanganan lanjutan","Dapat diterima") -> Dapat diterima | R10: =IF(E10="Kritis","Direksi",IF(E10="Tinggi","Manajemen",IF(E10="Sedang","Pemilik risiko","Tidak perlu"))) -> Manajemen
A11: R-02 | B11: G1 | C11: =INDEX('Risk Register'!$C$6:$C$27,MATCH($A11,'Risk Register'!$A$6:$A$27,0)) -> Data KTP dan swafoto pengguna bocor atau disalahgunakan | D11: =INDEX('Risk Register'!$J$6:$J$27,MATCH($A11,'Risk Register'!$A$6:$A$27,0)) -> 12 | E11: =INDEX('Risk Register'!$K$6:$K$27,MATCH($A11,'Risk Register'!$A$6:$A$27,0)) -> Tinggi | F11: =MATCH($A11,Evaluasi!$B$10:$B$31,0) -> 5 | G11: Mitigasi | H11: 5.15, 5.18, 8.2, 8.3, 8.5, 8.15 | I11: Hak akses berbasis peran (least privilege) ke data KYC, MFA wajib untuk semua akses, tinjauan hak akses tiap 3 bulan, log akses data KYC dipantau. | J11: Skor 12 di atas batas; membatasi siapa yang bisa mengakses menurunkan kemungkinan, dampak data bocor tetap besar. | K11: =INDEX('Risk Register'!$D$6:$D$27,MATCH($A11,'Risk Register'!$A$6:$A$27,0)) -> Compliance Officer | L11: =IF(G11="Terima",EDATE($D$6,6),$D$6+Evaluasi!$D$6) -> 46397 | M11: 2 | N11: 4 | O11: =M11*N11 -> 8 | P11: =IF(O11<=Kriteria!$B$3,"Rendah",IF(O11<=Kriteria!$B$4,"Sedang",IF(O11<=Kriteria!$B$5,"Tinggi","Kritis"))) -> Sedang | Q11: =IF(O11>Kriteria!$B$6,"Perlu penanganan lanjutan","Dapat diterima") -> Dapat diterima | R11: =IF(E11="Kritis","Direksi",IF(E11="Tinggi","Manajemen",IF(E11="Sedang","Pemilik risiko","Tidak perlu"))) -> Manajemen
A12: R-03 | B12: G5 | C12: =INDEX('Risk Register'!$C$6:$C$27,MATCH($A12,'Risk Register'!$A$6:$A$27,0)) -> File KYC terekspos ke internet | D12: =INDEX('Risk Register'!$J$6:$J$27,MATCH($A12,'Risk Register'!$A$6:$A$27,0)) -> 10 | E12: =INDEX('Risk Register'!$K$6:$K$27,MATCH($A12,'Risk Register'!$A$6:$A$27,0)) -> Tinggi | F12: =MATCH($A12,Evaluasi!$B$10:$B$31,0) -> 9 | G12: Mitigasi | H12: 8.9, 8.3, 8.24, 8.16, 5.23 | I12: Blok akses publik pada object storage secara default, enkripsi at-rest, baseline konfigurasi cloud dengan pemindaian otomatis dan alert jika ada perubahan. | J12: Skor 10 di atas batas; konfigurasi yang dijaga otomatis hampir menutup kemungkinan salah konfigurasi. | K12: =INDEX('Risk Register'!$D$6:$D$27,MATCH($A12,'Risk Register'!$A$6:$A$27,0)) -> Head of Infrastructure | L12: =IF(G12="Terima",EDATE($D$6,6),$D$6+Evaluasi!$D$6) -> 46397 | M12: 1 | N12: 5 | O12: =M12*N12 -> 5 | P12: =IF(O12<=Kriteria!$B$3,"Rendah",IF(O12<=Kriteria!$B$4,"Sedang",IF(O12<=Kriteria!$B$5,"Tinggi","Kritis"))) -> Sedang | Q12: =IF(O12>Kriteria!$B$6,"Perlu penanganan lanjutan","Dapat diterima") -> Dapat diterima | R12: =IF(E12="Kritis","Direksi",IF(E12="Tinggi","Manajemen",IF(E12="Sedang","Pemilik risiko","Tidak perlu"))) -> Manajemen
A13: R-04 | B13: G1 | C13: =INDEX('Risk Register'!$C$6:$C$27,MATCH($A13,'Risk Register'!$A$6:$A$27,0)) -> Saldo atau mutasi diubah tanpa terdeteksi | D13: =INDEX('Risk Register'!$J$6:$J$27,MATCH($A13,'Risk Register'!$A$6:$A$27,0)) -> 10 | E13: =INDEX('Risk Register'!$K$6:$K$27,MATCH($A13,'Risk Register'!$A$6:$A$27,0)) -> Tinggi | F13: =MATCH($A13,Evaluasi!$B$10:$B$31,0) -> 10 | G13: Mitigasi | H13: 5.3, 8.3, 8.2, 8.15 | I13: Pemisahan tugas antara pengubah dan penyetuju data ledger, rekonsiliasi otomatis harian, log perubahan ledger yang tidak bisa diubah. | J13: Skor 10 di atas batas; dampak finansial tetap besar jika terjadi, jadi yang ditekan adalah kemungkinan dan deteksi. | K13: =INDEX('Risk Register'!$D$6:$D$27,MATCH($A13,'Risk Register'!$A$6:$A$27,0)) -> Head of Finance Operations | L13: =IF(G13="Terima",EDATE($D$6,6),$D$6+Evaluasi!$D$6) -> 46397 | M13: 1 | N13: 5 | O13: =M13*N13 -> 5 | P13: =IF(O13<=Kriteria!$B$3,"Rendah",IF(O13<=Kriteria!$B$4,"Sedang",IF(O13<=Kriteria!$B$5,"Tinggi","Kritis"))) -> Sedang | Q13: =IF(O13>Kriteria!$B$6,"Perlu penanganan lanjutan","Dapat diterima") -> Dapat diterima | R13: =IF(E13="Kritis","Direksi",IF(E13="Tinggi","Manajemen",IF(E13="Sedang","Pemilik risiko","Tidak perlu"))) -> Manajemen
A14: R-05 | B14: G2 | C14: =INDEX('Risk Register'!$C$6:$C$27,MATCH($A14,'Risk Register'!$A$6:$A$27,0)) -> Kunci jatuh ke penyerang sehingga data terenkripsi bisa dibuka | D14: =INDEX('Risk Register'!$J$6:$J$27,MATCH($A14,'Risk Register'!$A$6:$A$27,0)) -> 12 | E14: =INDEX('Risk Register'!$K$6:$K$27,MATCH($A14,'Risk Register'!$A$6:$A$27,0)) -> Tinggi | F14: =MATCH($A14,Evaluasi!$B$10:$B$31,0) -> 6 | G14: Mitigasi | H14: 8.24, 5.17, 8.28, 8.4 | I14: Semua secret dipindah ke secrets manager, secret scanning di repositori dan pipeline, rotasi kunci terjadwal, larangan menyimpan secret di kode dan chat. | J14: Skor 12 di atas batas; akar masalah (secret di kode) dihilangkan, dampak kebocoran kunci tetap serius. | K14: =INDEX('Risk Register'!$D$6:$D$27,MATCH($A14,'Risk Register'!$A$6:$A$27,0)) -> Head of Security | L14: =IF(G14="Terima",EDATE($D$6,6),$D$6+Evaluasi!$D$6) -> 46397 | M14: 2 | N14: 4 | O14: =M14*N14 -> 8 | P14: =IF(O14<=Kriteria!$B$3,"Rendah",IF(O14<=Kriteria!$B$4,"Sedang",IF(O14<=Kriteria!$B$5,"Tinggi","Kritis"))) -> Sedang | Q14: =IF(O14>Kriteria!$B$6,"Perlu penanganan lanjutan","Dapat diterima") -> Dapat diterima | R14: =IF(E14="Kritis","Direksi",IF(E14="Tinggi","Manajemen",IF(E14="Sedang","Pemilik risiko","Tidak perlu"))) -> Manajemen
A15: R-06 | B15: G2 | C15: =INDEX('Risk Register'!$C$6:$C$27,MATCH($A15,'Risk Register'!$A$6:$A$27,0)) -> Kode sumber bocor sehingga celah aplikasi dan logika bisnis terlihat pihak yang tidak berwenang | D15: =INDEX('Risk Register'!$J$6:$J$27,MATCH($A15,'Risk Register'!$A$6:$A$27,0)) -> 9 | E15: =INDEX('Risk Register'!$K$6:$K$27,MATCH($A15,'Risk Register'!$A$6:$A$27,0)) -> Sedang | F15: =MATCH($A15,Evaluasi!$B$10:$B$31,0) -> 13 | G15: Mitigasi | H15: 8.4, 5.18, 8.5, 8.3 | I15: Repositori privat secara default dengan kontrol publikasi, MFA wajib, pencabutan akun mantan karyawan, tinjauan akses repositori tiap 3 bulan. | J15: Skor 9 sebenarnya boleh diterima, tetapi kontrolnya sama dengan R-05 dan R-07 sehingga ditangani bersama dalam satu kelompok. | K15: =INDEX('Risk Register'!$D$6:$D$27,MATCH($A15,'Risk Register'!$A$6:$A$27,0)) -> Head of Engineering | L15: =IF(G15="Terima",EDATE($D$6,6),$D$6+Evaluasi!$D$6) -> 46397 | M15: 2 | N15: 3 | O15: =M15*N15 -> 6 | P15: =IF(O15<=Kriteria!$B$3,"Rendah",IF(O15<=Kriteria!$B$4,"Sedang",IF(O15<=Kriteria!$B$5,"Tinggi","Kritis"))) -> Sedang | Q15: =IF(O15>Kriteria!$B$6,"Perlu penanganan lanjutan","Dapat diterima") -> Dapat diterima | R15: =IF(E15="Kritis","Direksi",IF(E15="Tinggi","Manajemen",IF(E15="Sedang","Pemilik risiko","Tidak perlu"))) -> Pemilik risiko
A16: R-07 | B16: G2 | C16: =INDEX('Risk Register'!$C$6:$C$27,MATCH($A16,'Risk Register'!$A$6:$A$27,0)) -> Kode atau pipeline diubah tanpa izin sehingga kode berbahaya masuk ke produksi dan dana atau data pengguna disalahgunakan | D16: =INDEX('Risk Register'!$J$6:$J$27,MATCH($A16,'Risk Register'!$A$6:$A$27,0)) -> 15 | E16: =INDEX('Risk Register'!$K$6:$K$27,MATCH($A16,'Risk Register'!$A$6:$A$27,0)) -> Tinggi | F16: =MATCH($A16,Evaluasi!$B$10:$B$31,0) -> 3 | G16: Mitigasi | H16: 8.4, 8.32, 5.18, 8.5, 8.25 | I16: Branch protection dan review kode wajib dua orang, deploy ke produksi lewat persetujuan, MFA wajib pada repositori dan pipeline, pencabutan akun lama, pemantauan perubahan pipeline. | J16: Skor 15 di atas batas; akibat tetap berat jika lolos, jadi dibutuhkan lapisan persetujuan deploy dan deteksi agar dampak sisa turun. | K16: =INDEX('Risk Register'!$D$6:$D$27,MATCH($A16,'Risk Register'!$A$6:$A$27,0)) -> Head of Engineering | L16: =IF(G16="Terima",EDATE($D$6,6),$D$6+Evaluasi!$D$6) -> 46397 | M16: 2 | N16: 4 | O16: =M16*N16 -> 8 | P16: =IF(O16<=Kriteria!$B$3,"Rendah",IF(O16<=Kriteria!$B$4,"Sedang",IF(O16<=Kriteria!$B$5,"Tinggi","Kritis"))) -> Sedang | Q16: =IF(O16>Kriteria!$B$6,"Perlu penanganan lanjutan","Dapat diterima") -> Dapat diterima | R16: =IF(E16="Kritis","Direksi",IF(E16="Tinggi","Manajemen",IF(E16="Sedang","Pemilik risiko","Tidak perlu"))) -> Manajemen
A17: R-08 | B17: - | C17: =INDEX('Risk Register'!$C$6:$C$27,MATCH($A17,'Risk Register'!$A$6:$A$27,0)) -> Kebijakan usang atau berubah tanpa persetujuan, kewajiban hukum terlewat | D17: =INDEX('Risk Register'!$J$6:$J$27,MATCH($A17,'Risk Register'!$A$6:$A$27,0)) -> 6 | E17: =INDEX('Risk Register'!$K$6:$K$27,MATCH($A17,'Risk Register'!$A$6:$A$27,0)) -> Sedang | F17: =MATCH($A17,Evaluasi!$B$10:$B$31,0) -> 22 | G17: Terima | H17: - | I17: Dipantau pada tinjauan berkala 6 bulan. | J17: Skor 6, di bawah batas penerimaan; dampak operasional kecil. | K17: =INDEX('Risk Register'!$D$6:$D$27,MATCH($A17,'Risk Register'!$A$6:$A$27,0)) -> Compliance Officer | L17: =IF(G17="Terima",EDATE($D$6,6),$D$6+Evaluasi!$D$6) -> 46489 | M17: =INDEX('Risk Register'!$E$6:$E$27,MATCH($A17,'Risk Register'!$A$6:$A$27,0)) -> 3 | N17: =INDEX('Risk Register'!$I$6:$I$27,MATCH($A17,'Risk Register'!$A$6:$A$27,0)) -> 2 | O17: =M17*N17 -> 6 | P17: =IF(O17<=Kriteria!$B$3,"Rendah",IF(O17<=Kriteria!$B$4,"Sedang",IF(O17<=Kriteria!$B$5,"Tinggi","Kritis"))) -> Sedang | Q17: =IF(O17>Kriteria!$B$6,"Perlu penanganan lanjutan","Dapat diterima") -> Dapat diterima | R17: =IF(E17="Kritis","Direksi",IF(E17="Tinggi","Manajemen",IF(E17="Sedang","Pemilik risiko","Tidak perlu"))) -> Pemilik risiko
A18: R-09 | B18: - | C18: =INDEX('Risk Register'!$C$6:$C$27,MATCH($A18,'Risk Register'!$A$6:$A$27,0)) -> Aplikasi palsu mencuri kredensial pengguna | D18: =INDEX('Risk Register'!$J$6:$J$27,MATCH($A18,'Risk Register'!$A$6:$A$27,0)) -> 9 | E18: =INDEX('Risk Register'!$K$6:$K$27,MATCH($A18,'Risk Register'!$A$6:$A$27,0)) -> Sedang | F18: =MATCH($A18,Evaluasi!$B$10:$B$31,0) -> 14 | G18: Terima | H18: - | I18: Dipantau pada tinjauan berkala 6 bulan; laporan pengguna soal aplikasi tiruan ditindaklanjuti. | J18: Skor 9, tepat di batas penerimaan; ditinjau tiap 6 bulan. | K18: =INDEX('Risk Register'!$D$6:$D$27,MATCH($A18,'Risk Register'!$A$6:$A$27,0)) -> Product Owner | L18: =IF(G18="Terima",EDATE($D$6,6),$D$6+Evaluasi!$D$6) -> 46489 | M18: =INDEX('Risk Register'!$E$6:$E$27,MATCH($A18,'Risk Register'!$A$6:$A$27,0)) -> 3 | N18: =INDEX('Risk Register'!$I$6:$I$27,MATCH($A18,'Risk Register'!$A$6:$A$27,0)) -> 3 | O18: =M18*N18 -> 9 | P18: =IF(O18<=Kriteria!$B$3,"Rendah",IF(O18<=Kriteria!$B$4,"Sedang",IF(O18<=Kriteria!$B$5,"Tinggi","Kritis"))) -> Sedang | Q18: =IF(O18>Kriteria!$B$6,"Perlu penanganan lanjutan","Dapat diterima") -> Dapat diterima | R18: =IF(E18="Kritis","Direksi",IF(E18="Tinggi","Manajemen",IF(E18="Sedang","Pemilik risiko","Tidak perlu"))) -> Pemilik risiko
A19: R-10 | B19: G4 | C19: =INDEX('Risk Register'!$C$6:$C$27,MATCH($A19,'Risk Register'!$A$6:$A$27,0)) -> API tidak tersedia, transaksi merchant gagal | D19: =INDEX('Risk Register'!$J$6:$J$27,MATCH($A19,'Risk Register'!$A$6:$A$27,0)) -> 16 | E19: =INDEX('Risk Register'!$K$6:$K$27,MATCH($A19,'Risk Register'!$A$6:$A$27,0)) -> Tinggi | F19: =MATCH($A19,Evaluasi!$B$10:$B$31,0) -> 1 | G19: Mitigasi | H19: 8.6, 8.20, 8.21, 8.16 | I19: Rate limiting pada API, layanan proteksi DDoS dari penyedia cloud atau CDN, autoscaling dan pemantauan lonjakan trafik. | J19: Skor 16 tertinggi; serangan DDoS tidak bisa dicegah sepenuhnya, jadi tujuannya memperkecil frekuensi berhasil dan durasi gangguan. | K19: =INDEX('Risk Register'!$D$6:$D$27,MATCH($A19,'Risk Register'!$A$6:$A$27,0)) -> Head of Engineering | L19: =IF(G19="Terima",EDATE($D$6,6),$D$6+Evaluasi!$D$6) -> 46397 | M19: 2 | N19: 3 | O19: =M19*N19 -> 6 | P19: =IF(O19<=Kriteria!$B$3,"Rendah",IF(O19<=Kriteria!$B$4,"Sedang",IF(O19<=Kriteria!$B$5,"Tinggi","Kritis"))) -> Sedang | Q19: =IF(O19>Kriteria!$B$6,"Perlu penanganan lanjutan","Dapat diterima") -> Dapat diterima | R19: =IF(E19="Kritis","Direksi",IF(E19="Tinggi","Manajemen",IF(E19="Sedang","Pemilik risiko","Tidak perlu"))) -> Manajemen
A20: R-11 | B20: G3 | C20: =INDEX('Risk Register'!$C$6:$C$27,MATCH($A20,'Risk Register'!$A$6:$A$27,0)) -> Penyerang mengakses transaksi merchant lain | D20: =INDEX('Risk Register'!$J$6:$J$27,MATCH($A20,'Risk Register'!$A$6:$A$27,0)) -> 12 | E20: =INDEX('Risk Register'!$K$6:$K$27,MATCH($A20,'Risk Register'!$A$6:$A$27,0)) -> Tinggi | F20: =MATCH($A20,Evaluasi!$B$10:$B$31,0) -> 7 | G20: Mitigasi | H20: 8.26, 8.28, 8.29, 8.3, 8.16 | I20: Otorisasi per objek diuji di setiap endpoint, pentest API berkala, pemantauan pola akses tidak wajar. | J20: Skor 12 di atas batas; celah otorisasi ditutup di kode dan diuji berkala. | K20: =INDEX('Risk Register'!$D$6:$D$27,MATCH($A20,'Risk Register'!$A$6:$A$27,0)) -> Head of Engineering | L20: =IF(G20="Terima",EDATE($D$6,6),$D$6+Evaluasi!$D$6) -> 46397 | M20: 2 | N20: 4 | O20: =M20*N20 -> 8 | P20: =IF(O20<=Kriteria!$B$3,"Rendah",IF(O20<=Kriteria!$B$4,"Sedang",IF(O20<=Kriteria!$B$5,"Tinggi","Kritis"))) -> Sedang | Q20: =IF(O20>Kriteria!$B$6,"Perlu penanganan lanjutan","Dapat diterima") -> Dapat diterima | R20: =IF(E20="Kritis","Direksi",IF(E20="Tinggi","Manajemen",IF(E20="Sedang","Pemilik risiko","Tidak perlu"))) -> Manajemen
A21: R-12 | B21: G1 | C21: =INDEX('Risk Register'!$C$6:$C$27,MATCH($A21,'Risk Register'!$A$6:$A$27,0)) -> Akun merchant diambil alih dan dana dialihkan | D21: =INDEX('Risk Register'!$J$6:$J$27,MATCH($A21,'Risk Register'!$A$6:$A$27,0)) -> 12 | E21: =INDEX('Risk Register'!$K$6:$K$27,MATCH($A21,'Risk Register'!$A$6:$A$27,0)) -> Tinggi | F21: =MATCH($A21,Evaluasi!$B$10:$B$31,0) -> 8 | G21: Mitigasi | H21: 8.5, 5.17, 8.16 | I21: MFA wajib untuk akun merchant, kebijakan kata sandi dan pengecekan kata sandi bocor, deteksi login anomali dan pembatasan percobaan. | J21: Skor 12 di atas batas; MFA langsung memutus credential stuffing. | K21: =INDEX('Risk Register'!$D$6:$D$27,MATCH($A21,'Risk Register'!$A$6:$A$27,0)) -> Product Owner | L21: =IF(G21="Terima",EDATE($D$6,6),$D$6+Evaluasi!$D$6) -> 46397 | M21: 2 | N21: 3 | O21: =M21*N21 -> 6 | P21: =IF(O21<=Kriteria!$B$3,"Rendah",IF(O21<=Kriteria!$B$4,"Sedang",IF(O21<=Kriteria!$B$5,"Tinggi","Kritis"))) -> Sedang | Q21: =IF(O21>Kriteria!$B$6,"Perlu penanganan lanjutan","Dapat diterima") -> Dapat diterima | R21: =IF(E21="Kritis","Direksi",IF(E21="Tinggi","Manajemen",IF(E21="Sedang","Pemilik risiko","Tidak perlu"))) -> Manajemen
A22: R-13 | B22: G7 | C22: =INDEX('Risk Register'!$C$6:$C$27,MATCH($A22,'Risk Register'!$A$6:$A$27,0)) -> Insiden tidak terdeteksi atau tidak bisa diselidiki | D22: =INDEX('Risk Register'!$J$6:$J$27,MATCH($A22,'Risk Register'!$A$6:$A$27,0)) -> 9 | E22: =INDEX('Risk Register'!$K$6:$K$27,MATCH($A22,'Risk Register'!$A$6:$A$27,0)) -> Sedang | F22: =MATCH($A22,Evaluasi!$B$10:$B$31,0) -> 15 | G22: Mitigasi | H22: 8.15, 8.16 | I22: Retensi log minimal 12 bulan, perlindungan integritas log, alerting untuk kejadian kritis. | J22: Skor 9 boleh diterima, tetapi kontrol deteksi di kelompok lain (R-02, R-04, R-10, R-11) bergantung pada log yang memadai. | K22: =INDEX('Risk Register'!$D$6:$D$27,MATCH($A22,'Risk Register'!$A$6:$A$27,0)) -> Head of Security | L22: =IF(G22="Terima",EDATE($D$6,6),$D$6+Evaluasi!$D$6) -> 46397 | M22: 2 | N22: 3 | O22: =M22*N22 -> 6 | P22: =IF(O22<=Kriteria!$B$3,"Rendah",IF(O22<=Kriteria!$B$4,"Sedang",IF(O22<=Kriteria!$B$5,"Tinggi","Kritis"))) -> Sedang | Q22: =IF(O22>Kriteria!$B$6,"Perlu penanganan lanjutan","Dapat diterima") -> Dapat diterima | R22: =IF(E22="Kritis","Direksi",IF(E22="Tinggi","Manajemen",IF(E22="Sedang","Pemilik risiko","Tidak perlu"))) -> Pemilik risiko
A23: R-14 | B23: - | C23: =INDEX('Risk Register'!$C$6:$C$27,MATCH($A23,'Risk Register'!$A$6:$A$27,0)) -> Layanan berhenti berjam-jam | D23: =INDEX('Risk Register'!$J$6:$J$27,MATCH($A23,'Risk Register'!$A$6:$A$27,0)) -> 8 | E23: =INDEX('Risk Register'!$K$6:$K$27,MATCH($A23,'Risk Register'!$A$6:$A$27,0)) -> Sedang | F23: =MATCH($A23,Evaluasi!$B$10:$B$31,0) -> 19 | G23: Terima | H23: - | I23: Dipantau pada tinjauan berkala 6 bulan. | J23: Skor 8; gangguan penyedia cloud ditoleransi sesuai SLA penyedia. | K23: =INDEX('Risk Register'!$D$6:$D$27,MATCH($A23,'Risk Register'!$A$6:$A$27,0)) -> Head of Infrastructure | L23: =IF(G23="Terima",EDATE($D$6,6),$D$6+Evaluasi!$D$6) -> 46489 | M23: =INDEX('Risk Register'!$E$6:$E$27,MATCH($A23,'Risk Register'!$A$6:$A$27,0)) -> 2 | N23: =INDEX('Risk Register'!$I$6:$I$27,MATCH($A23,'Risk Register'!$A$6:$A$27,0)) -> 4 | O23: =M23*N23 -> 8 | P23: =IF(O23<=Kriteria!$B$3,"Rendah",IF(O23<=Kriteria!$B$4,"Sedang",IF(O23<=Kriteria!$B$5,"Tinggi","Kritis"))) -> Sedang | Q23: =IF(O23>Kriteria!$B$6,"Perlu penanganan lanjutan","Dapat diterima") -> Dapat diterima | R23: =IF(E23="Kritis","Direksi",IF(E23="Tinggi","Manajemen",IF(E23="Sedang","Pemilik risiko","Tidak perlu"))) -> Pemilik risiko
A24: R-15 | B24: G4 | C24: =INDEX('Risk Register'!$C$6:$C$27,MATCH($A24,'Risk Register'!$A$6:$A$27,0)) -> Data produksi terenkripsi dan backup ikut rusak | D24: =INDEX('Risk Register'!$J$6:$J$27,MATCH($A24,'Risk Register'!$A$6:$A$27,0)) -> 10 | E24: =INDEX('Risk Register'!$K$6:$K$27,MATCH($A24,'Risk Register'!$A$6:$A$27,0)) -> Tinggi | F24: =MATCH($A24,Evaluasi!$B$10:$B$31,0) -> 11 | G24: Mitigasi dan transfer | H24: 8.13, 8.7, 5.30, 8.14, 5.29 | I24: Backup terisolasi (immutable) dengan uji pemulihan berkala, proteksi endpoint dan server, rencana pemulihan dengan target waktu; sebagian risiko dialihkan lewat asuransi siber. | J24: Skor 10 di atas batas; backup teruji menurunkan dampak, asuransi mengalihkan sebagian kerugian finansial. | K24: =INDEX('Risk Register'!$D$6:$D$27,MATCH($A24,'Risk Register'!$A$6:$A$27,0)) -> Head of Infrastructure | L24: =IF(G24="Terima",EDATE($D$6,6),$D$6+Evaluasi!$D$6) -> 46397 | M24: 2 | N24: 3 | O24: =M24*N24 -> 6 | P24: =IF(O24<=Kriteria!$B$3,"Rendah",IF(O24<=Kriteria!$B$4,"Sedang",IF(O24<=Kriteria!$B$5,"Tinggi","Kritis"))) -> Sedang | Q24: =IF(O24>Kriteria!$B$6,"Perlu penanganan lanjutan","Dapat diterima") -> Dapat diterima | R24: =IF(E24="Kritis","Direksi",IF(E24="Tinggi","Manajemen",IF(E24="Sedang","Pemilik risiko","Tidak perlu"))) -> Manajemen
A25: R-16 | B25: - | C25: =INDEX('Risk Register'!$C$6:$C$27,MATCH($A25,'Risk Register'!$A$6:$A$27,0)) -> Penyerang di jaringan kantor menjangkau sistem internal | D25: =INDEX('Risk Register'!$J$6:$J$27,MATCH($A25,'Risk Register'!$A$6:$A$27,0)) -> 6 | E25: =INDEX('Risk Register'!$K$6:$K$27,MATCH($A25,'Risk Register'!$A$6:$A$27,0)) -> Sedang | F25: =MATCH($A25,Evaluasi!$B$10:$B$31,0) -> 21 | G25: Terima | H25: - | I25: Dipantau pada tinjauan berkala 6 bulan. | J25: Skor 6; sistem produksi berada di cloud sehingga jangkauan dari jaringan kantor terbatas. | K25: =INDEX('Risk Register'!$D$6:$D$27,MATCH($A25,'Risk Register'!$A$6:$A$27,0)) -> Head of Infrastructure | L25: =IF(G25="Terima",EDATE($D$6,6),$D$6+Evaluasi!$D$6) -> 46489 | M25: =INDEX('Risk Register'!$E$6:$E$27,MATCH($A25,'Risk Register'!$A$6:$A$27,0)) -> 2 | N25: =INDEX('Risk Register'!$I$6:$I$27,MATCH($A25,'Risk Register'!$A$6:$A$27,0)) -> 3 | O25: =M25*N25 -> 6 | P25: =IF(O25<=Kriteria!$B$3,"Rendah",IF(O25<=Kriteria!$B$4,"Sedang",IF(O25<=Kriteria!$B$5,"Tinggi","Kritis"))) -> Sedang | Q25: =IF(O25>Kriteria!$B$6,"Perlu penanganan lanjutan","Dapat diterima") -> Dapat diterima | R25: =IF(E25="Kritis","Direksi",IF(E25="Tinggi","Manajemen",IF(E25="Sedang","Pemilik risiko","Tidak perlu"))) -> Pemilik risiko
A26: R-17 | B26: - | C26: =INDEX('Risk Register'!$C$6:$C$27,MATCH($A26,'Risk Register'!$A$6:$A$27,0)) -> Data perusahaan bocor dari laptop | D26: =INDEX('Risk Register'!$J$6:$J$27,MATCH($A26,'Risk Register'!$A$6:$A$27,0)) -> 9 | E26: =INDEX('Risk Register'!$K$6:$K$27,MATCH($A26,'Risk Register'!$A$6:$A$27,0)) -> Sedang | F26: =MATCH($A26,Evaluasi!$B$10:$B$31,0) -> 16 | G26: Terima | H26: - | I26: Dipantau pada tinjauan berkala 6 bulan. | J26: Skor 9, tepat di batas penerimaan; enkripsi disk ditunda karena keterbatasan anggaran. | K26: =INDEX('Risk Register'!$D$6:$D$27,MATCH($A26,'Risk Register'!$A$6:$A$27,0)) -> Head of IT Support | L26: =IF(G26="Terima",EDATE($D$6,6),$D$6+Evaluasi!$D$6) -> 46489 | M26: =INDEX('Risk Register'!$E$6:$E$27,MATCH($A26,'Risk Register'!$A$6:$A$27,0)) -> 3 | N26: =INDEX('Risk Register'!$I$6:$I$27,MATCH($A26,'Risk Register'!$A$6:$A$27,0)) -> 3 | O26: =M26*N26 -> 9 | P26: =IF(O26<=Kriteria!$B$3,"Rendah",IF(O26<=Kriteria!$B$4,"Sedang",IF(O26<=Kriteria!$B$5,"Tinggi","Kritis"))) -> Sedang | Q26: =IF(O26>Kriteria!$B$6,"Perlu penanganan lanjutan","Dapat diterima") -> Dapat diterima | R26: =IF(E26="Kritis","Direksi",IF(E26="Tinggi","Manajemen",IF(E26="Sedang","Pemilik risiko","Tidak perlu"))) -> Pemilik risiko
A27: R-18 | B27: G1 | C27: =INDEX('Risk Register'!$C$6:$C$27,MATCH($A27,'Risk Register'!$A$6:$A$27,0)) -> Karyawan menyerahkan kredensial dan penyerang masuk ke sistem | D27: =INDEX('Risk Register'!$J$6:$J$27,MATCH($A27,'Risk Register'!$A$6:$A$27,0)) -> 16 | E27: =INDEX('Risk Register'!$K$6:$K$27,MATCH($A27,'Risk Register'!$A$6:$A$27,0)) -> Tinggi | F27: =MATCH($A27,Evaluasi!$B$10:$B$31,0) -> 2 | G27: Mitigasi | H27: 6.3, 8.23, 8.7, 8.5, 6.8 | I27: Pelatihan dan simulasi phishing berkala, filter email dan web, MFA tahan phishing untuk sistem kritis, jalur pelaporan email mencurigakan. | J27: Skor 16 tertinggi; phishing tidak bisa dihilangkan, jadi MFA dibuat agar kredensial curian tidak cukup. | K27: =INDEX('Risk Register'!$D$6:$D$27,MATCH($A27,'Risk Register'!$A$6:$A$27,0)) -> Head of IT Support | L27: =IF(G27="Terima",EDATE($D$6,6),$D$6+Evaluasi!$D$6) -> 46397 | M27: 2 | N27: 3 | O27: =M27*N27 -> 6 | P27: =IF(O27<=Kriteria!$B$3,"Rendah",IF(O27<=Kriteria!$B$4,"Sedang",IF(O27<=Kriteria!$B$5,"Tinggi","Kritis"))) -> Sedang | Q27: =IF(O27>Kriteria!$B$6,"Perlu penanganan lanjutan","Dapat diterima") -> Dapat diterima | R27: =IF(E27="Kritis","Direksi",IF(E27="Tinggi","Manajemen",IF(E27="Sedang","Pemilik risiko","Tidak perlu"))) -> Manajemen
A28: R-19 | B28: - | C28: =INDEX('Risk Register'!$C$6:$C$27,MATCH($A28,'Risk Register'!$A$6:$A$27,0)) -> Transaksi tertahan atau disusupi | D28: =INDEX('Risk Register'!$J$6:$J$27,MATCH($A28,'Risk Register'!$A$6:$A$27,0)) -> 8 | E28: =INDEX('Risk Register'!$K$6:$K$27,MATCH($A28,'Risk Register'!$A$6:$A$27,0)) -> Sedang | F28: =MATCH($A28,Evaluasi!$B$10:$B$31,0) -> 20 | G28: Terima | H28: - | I28: Dipantau pada tinjauan berkala 6 bulan. | J28: Skor 8; terkendali lewat SLA dan kontak teknis dengan bank mitra. | K28: =INDEX('Risk Register'!$D$6:$D$27,MATCH($A28,'Risk Register'!$A$6:$A$27,0)) -> Head of Partnership | L28: =IF(G28="Terima",EDATE($D$6,6),$D$6+Evaluasi!$D$6) -> 46489 | M28: =INDEX('Risk Register'!$E$6:$E$27,MATCH($A28,'Risk Register'!$A$6:$A$27,0)) -> 2 | N28: =INDEX('Risk Register'!$I$6:$I$27,MATCH($A28,'Risk Register'!$A$6:$A$27,0)) -> 4 | O28: =M28*N28 -> 8 | P28: =IF(O28<=Kriteria!$B$3,"Rendah",IF(O28<=Kriteria!$B$4,"Sedang",IF(O28<=Kriteria!$B$5,"Tinggi","Kritis"))) -> Sedang | Q28: =IF(O28>Kriteria!$B$6,"Perlu penanganan lanjutan","Dapat diterima") -> Dapat diterima | R28: =IF(E28="Kritis","Direksi",IF(E28="Tinggi","Manajemen",IF(E28="Sedang","Pemilik risiko","Tidak perlu"))) -> Pemilik risiko
A29: R-20 | B29: G6 | C29: =INDEX('Risk Register'!$C$6:$C$27,MATCH($A29,'Risk Register'!$A$6:$A$27,0)) -> Data KYC pengguna bocor dari penyedia | D29: =INDEX('Risk Register'!$J$6:$J$27,MATCH($A29,'Risk Register'!$A$6:$A$27,0)) -> 10 | E29: =INDEX('Risk Register'!$K$6:$K$27,MATCH($A29,'Risk Register'!$A$6:$A$27,0)) -> Tinggi | F29: =MATCH($A29,Evaluasi!$B$10:$B$31,0) -> 12 | G29: Mitigasi dan transfer | H29: 5.19, 5.20, 5.22, 5.34 | I29: Penilaian keamanan vendor sebelum dan berkala, klausul keamanan dan notifikasi insiden di kontrak, batasi retensi data di vendor, ganti rugi kontraktual. | J29: Skor 10 di atas batas; LumiPay tidak mengendalikan sistem vendor, jadi kontrol berupa pengawasan dan kontrak, dengan transfer sebagian risiko lewat kontrak. | K29: =INDEX('Risk Register'!$D$6:$D$27,MATCH($A29,'Risk Register'!$A$6:$A$27,0)) -> Compliance Officer | L29: =IF(G29="Terima",EDATE($D$6,6),$D$6+Evaluasi!$D$6) -> 46397 | M29: 2 | N29: 4 | O29: =M29*N29 -> 8 | P29: =IF(O29<=Kriteria!$B$3,"Rendah",IF(O29<=Kriteria!$B$4,"Sedang",IF(O29<=Kriteria!$B$5,"Tinggi","Kritis"))) -> Sedang | Q29: =IF(O29>Kriteria!$B$6,"Perlu penanganan lanjutan","Dapat diterima") -> Dapat diterima | R29: =IF(E29="Kritis","Direksi",IF(E29="Tinggi","Manajemen",IF(E29="Sedang","Pemilik risiko","Tidak perlu"))) -> Manajemen
A30: R-21 | B30: - | C30: =INDEX('Risk Register'!$C$6:$C$27,MATCH($A30,'Risk Register'!$A$6:$A$27,0)) -> Pengguna tidak bisa login atau bertransaksi, atau OTP disalahgunakan | D30: =INDEX('Risk Register'!$J$6:$J$27,MATCH($A30,'Risk Register'!$A$6:$A$27,0)) -> 9 | E30: =INDEX('Risk Register'!$K$6:$K$27,MATCH($A30,'Risk Register'!$A$6:$A$27,0)) -> Sedang | F30: =MATCH($A30,Evaluasi!$B$10:$B$31,0) -> 17 | G30: Terima | H30: - | I30: Dipantau pada tinjauan berkala 6 bulan. | J30: Skor 9, tepat di batas penerimaan; ditinjau tiap 6 bulan. | K30: =INDEX('Risk Register'!$D$6:$D$27,MATCH($A30,'Risk Register'!$A$6:$A$27,0)) -> Head of Engineering | L30: =IF(G30="Terima",EDATE($D$6,6),$D$6+Evaluasi!$D$6) -> 46489 | M30: =INDEX('Risk Register'!$E$6:$E$27,MATCH($A30,'Risk Register'!$A$6:$A$27,0)) -> 3 | N30: =INDEX('Risk Register'!$I$6:$I$27,MATCH($A30,'Risk Register'!$A$6:$A$27,0)) -> 3 | O30: =M30*N30 -> 9 | P30: =IF(O30<=Kriteria!$B$3,"Rendah",IF(O30<=Kriteria!$B$4,"Sedang",IF(O30<=Kriteria!$B$5,"Tinggi","Kritis"))) -> Sedang | Q30: =IF(O30>Kriteria!$B$6,"Perlu penanganan lanjutan","Dapat diterima") -> Dapat diterima | R30: =IF(E30="Kritis","Direksi",IF(E30="Tinggi","Manajemen",IF(E30="Sedang","Pemilik risiko","Tidak perlu"))) -> Pemilik risiko
A31: R-22 | B31: - | C31: =INDEX('Risk Register'!$C$6:$C$27,MATCH($A31,'Risk Register'!$A$6:$A$27,0)) -> Pengetahuan kritis hilang dan akses mantan karyawan masih aktif | D31: =INDEX('Risk Register'!$J$6:$J$27,MATCH($A31,'Risk Register'!$A$6:$A$27,0)) -> 9 | E31: =INDEX('Risk Register'!$K$6:$K$27,MATCH($A31,'Risk Register'!$A$6:$A$27,0)) -> Sedang | F31: =MATCH($A31,Evaluasi!$B$10:$B$31,0) -> 18 | G31: Terima | H31: - | I31: Dipantau pada tinjauan berkala 6 bulan. | J31: Skor 9, tepat di batas penerimaan; ditinjau tiap 6 bulan. | K31: =INDEX('Risk Register'!$D$6:$D$27,MATCH($A31,'Risk Register'!$A$6:$A$27,0)) -> Head of HR | L31: =IF(G31="Terima",EDATE($D$6,6),$D$6+Evaluasi!$D$6) -> 46489 | M31: =INDEX('Risk Register'!$E$6:$E$27,MATCH($A31,'Risk Register'!$A$6:$A$27,0)) -> 3 | N31: =INDEX('Risk Register'!$I$6:$I$27,MATCH($A31,'Risk Register'!$A$6:$A$27,0)) -> 3 | O31: =M31*N31 -> 9 | P31: =IF(O31<=Kriteria!$B$3,"Rendah",IF(O31<=Kriteria!$B$4,"Sedang",IF(O31<=Kriteria!$B$5,"Tinggi","Kritis"))) -> Sedang | Q31: =IF(O31>Kriteria!$B$6,"Perlu penanganan lanjutan","Dapat diterima") -> Dapat diterima | R31: =IF(E31="Kritis","Direksi",IF(E31="Tinggi","Manajemen",IF(E31="Sedang","Pemilik risiko","Tidak perlu"))) -> Pemilik risiko
A33: Catatan: kontrol diambil dari ISO/IEC 27002:2022 (Annex A 27001:2022). Nilai risiko sisa adalah perkiraan setelah kontrol diterapkan dan perlu diverifikasi.
A34: Opsi 'Hindari' dan 'Transfer penuh' belum dipakai; transfer dipakai sebagian (R-15 dan R-20). Risiko yang diterima wajib punya alasan tertulis dan persetujuan pemilik risiko.

Sheet Kelompok
A1: Kelompok Penanganan Risiko
A2: Risiko yang akar masalahnya sama ditangani bersama, supaya satu perbaikan menutup beberapa risiko sekaligus.
A4: Kode | B4: Kelompok | C4: Akar masalah | D4: Risiko terkait | E4: Tindakan inti | F4: Kontrol Annex A utama | G4: Jumlah risiko
A5: G1 | B5: Akses dan autentikasi | C5: Akun dan hak akses kurang terlindungi (tanpa MFA, hak akses luas, akun lama). | D5: R-02, R-04, R-12, R-18 | E5: MFA wajib, hak akses minimum, tinjauan hak akses berkala, pemisahan tugas, pelatihan phishing. | F5: 5.3, 5.15, 5.18, 8.2, 8.5, 6.3 | G5: =COUNTIF(Penanganan!$B$10:$B$31,A5) -> 4
A6: G2 | B6: Kode dan pipeline | C6: Akses repositori dan pengelolaan secret lemah. | D6: R-05, R-06, R-07 | E6: Secrets manager dan secret scanning, MFA repositori, branch protection dan review wajib, pencabutan akun lama. | F6: 8.4, 8.24, 5.17, 8.32, 5.18, 8.5 | G6: =COUNTIF(Penanganan!$B$10:$B$31,A6) -> 3
A7: G3 | B7: Keamanan aplikasi dan API | C7: Kontrol keamanan saat pengembangan aplikasi dan API belum memadai. | D7: R-01, R-11 | E7: Secure coding, query berparameter, pengujian otorisasi per objek, SAST dan pentest, manajemen patch. | F7: 8.26, 8.28, 8.29, 8.8 | G7: =COUNTIF(Penanganan!$B$10:$B$31,A7) -> 2
A8: G4 | B8: Ketahanan layanan dan data | C8: Ketahanan terhadap serangan ketersediaan dan pemulihan data belum teruji. | D8: R-10, R-15 | E8: Rate limiting dan proteksi DDoS, backup terisolasi yang diuji, rencana pemulihan, asuransi siber. | F8: 8.6, 8.20, 8.21, 8.13, 5.30 | G8: =COUNTIF(Penanganan!$B$10:$B$31,A8) -> 2
A9: G5 | B9: Konfigurasi cloud | C9: Baseline konfigurasi cloud tidak dijaga otomatis. | D9: R-03 | E9: Blok akses publik, enkripsi at-rest, pemindaian konfigurasi dengan alert. | F9: 8.9, 8.3, 8.24, 5.23 | G9: =COUNTIF(Penanganan!$B$10:$B$31,A9) -> 1
A10: G6 | B10: Pihak ketiga | C10: Vendor pemroses data pribadi belum dinilai dan kontraknya belum memuat syarat keamanan. | D10: R-20 | E10: Penilaian vendor, klausul keamanan dan notifikasi insiden, batas retensi data, ganti rugi kontraktual. | F10: 5.19, 5.20, 5.22, 5.34 | G10: =COUNTIF(Penanganan!$B$10:$B$31,A10) -> 1
A11: G7 | B11: Pemantauan dan log | C11: Log tidak memadai, padahal dibutuhkan semua kontrol deteksi. | D11: R-13 | E11: Retensi log, perlindungan integritas log, alerting kejadian kritis. | F11: 8.15, 8.16 | G11: =COUNTIF(Penanganan!$B$10:$B$31,A11) -> 1

Sheet Kriteria
A1: Kriteria Risiko LumiPay (rujukan penilaian)
A2: Sel biru adalah parameter yang boleh diubah. Seluruh sheet lain membaca nilainya dari sini.
A3: Batas atas level Rendah (skor) | B3: 4
A4: Batas atas level Sedang (skor) | B4: 9
A5: Batas atas level Tinggi (skor) | B5: 16
A6: Batas penerimaan risiko (skor) | B6: =B4 -> 9
A7: Skor di atas batas Tinggi (16) masuk level Kritis (20 sampai 25). Batas penerimaan LumiPay sama dengan batas atas level Sedang.
A9: Matriks risiko: kemungkinan x dampak
A10: Kemungkinan \ Dampak | B10: 1 | C10: 2 | D10: 3 | E10: 4 | F10: 5
A11: 5 | B11: =$A11*B$10 -> 5 | C11: =$A11*C$10 -> 10 | D11: =$A11*D$10 -> 15 | E11: =$A11*E$10 -> 20 | F11: =$A11*F$10 -> 25
A12: 4 | B12: =$A12*B$10 -> 4 | C12: =$A12*C$10 -> 8 | D12: =$A12*D$10 -> 12 | E12: =$A12*E$10 -> 16 | F12: =$A12*F$10 -> 20
A13: 3 | B13: =$A13*B$10 -> 3 | C13: =$A13*C$10 -> 6 | D13: =$A13*D$10 -> 9 | E13: =$A13*E$10 -> 12 | F13: =$A13*F$10 -> 15
A14: 2 | B14: =$A14*B$10 -> 2 | C14: =$A14*C$10 -> 4 | D14: =$A14*D$10 -> 6 | E14: =$A14*E$10 -> 8 | F14: =$A14*F$10 -> 10
A15: 1 | B15: =$A15*B$10 -> 1 | C15: =$A15*C$10 -> 2 | D15: =$A15*D$10 -> 3 | E15: =$A15*E$10 -> 4 | F15: =$A15*F$10 -> 5
A17: Warna matriks memakai batas tetap 4, 9, dan 16 (sama dengan parameter di atas). Jika parameter diubah, sesuaikan aturan warnanya.

Sheet Ringkasan
A1: Ringkasan Hasil Analisis
A3: Level | B3: Jumlah risiko
A4: Rendah | B4: =COUNTIF('Risk Register'!$K$6:$K$27,A4) -> 0
A5: Sedang | B5: =COUNTIF('Risk Register'!$K$6:$K$27,A5) -> 10
A6: Tinggi | B6: =COUNTIF('Risk Register'!$K$6:$K$27,A6) -> 12
A7: Kritis | B7: =COUNTIF('Risk Register'!$K$6:$K$27,A7) -> 0
A8: Total risiko | B8: =SUM(B4:B7) -> 22
A9: Perlu ditangani (di atas batas penerimaan) | B9: =COUNTIF('Risk Register'!$L$6:$L$27,"Perlu ditangani") -> 12
A10: Skor tertinggi | B10: =MAX('Risk Register'!$J$6:$J$27) -> 16
A12: Penanganan risiko (langkah 5)
A13: Risiko dimitigasi (termasuk mitigasi dan transfer) | B13: =COUNTIF(Penanganan!$G$10:$G$31,"Mitigasi*") -> 14
A14: Risiko diterima | B14: =COUNTIF(Penanganan!$G$10:$G$31,"Terima") -> 8
A15: Risiko sisa di atas batas penerimaan | B15: =COUNTIF(Penanganan!$Q$10:$Q$31,"Perlu penanganan lanjutan") -> 0
A16: Skor sisa tertinggi | B16: =MAX(Penanganan!$O$10:$O$31) -> 9
A17: Jumlah kelompok penanganan | B17: =COUNTA(Kelompok!$A$5:$A$11) -> 7
A19: Cek Annex A dan SoA (langkah 6)
A20: Total kontrol dinilai | B20: =COUNTA(SoA!$A$7:$A$99) -> 93
A21: Kontrol berlaku | B21: =COUNTIF(SoA!$D$7:$D$99,"Ya") -> 84
A22: Kontrol tidak berlaku | B22: =COUNTIF(SoA!$D$7:$D$99,"Tidak") -> 9
A23: Berlaku karena dipilih dari risiko | B23: =COUNTIFS(SoA!$D$7:$D$99,"Ya",SoA!$E$7:$E$99,"Risiko") -> 34
A24: Berlaku karena hukum, kontrak, ISO, atau praktik dasar | B24: =B21-B23 -> 50
A25: Status Sudah diterapkan | B25: =COUNTIF(SoA!$I$7:$I$99,"Sudah diterapkan") -> 2
A26: Status Sebagian | B26: =COUNTIF(SoA!$I$7:$I$99,"Sebagian") -> 45
A27: Status Terencana | B27: =COUNTIF(SoA!$I$7:$I$99,"Terencana") -> 36
